[2025-01-31T01:31:42.465+0000] {local_task_job_runner.py:123} INFO - ::group::Pre task execution logs
[2025-01-31T01:31:42.479+0000] {taskinstance.py:2613} INFO - Dependencies all met for dep_context=non-requeueable deps ti=<TaskInstance: primeira_dag.tsk2 manual__2025-01-31T01:31:34.814321+00:00 [queued]>
[2025-01-31T01:31:42.484+0000] {taskinstance.py:2613} INFO - Dependencies all met for dep_context=requeueable deps ti=<TaskInstance: primeira_dag.tsk2 manual__2025-01-31T01:31:34.814321+00:00 [queued]>
[2025-01-31T01:31:42.484+0000] {taskinstance.py:2866} INFO - Starting attempt 1 of 1
[2025-01-31T01:31:42.492+0000] {taskinstance.py:2889} INFO - Executing <Task(BashOperator): tsk2> on 2025-01-31 01:31:34.814321+00:00
[2025-01-31T01:31:42.499+0000] {warnings.py:112} WARNING - /home/***/.local/lib/python3.12/site-packages/***/task/task_runner/standard_task_runner.py:70: DeprecationWarning: This process (pid=2977) is multi-threaded, use of fork() may lead to deadlocks in the child.
  pid = os.fork()

[2025-01-31T01:31:42.500+0000] {standard_task_runner.py:72} INFO - Started process 2978 to run task
[2025-01-31T01:31:42.500+0000] {standard_task_runner.py:104} INFO - Running: ['***', 'tasks', 'run', 'primeira_dag', 'tsk2', 'manual__2025-01-31T01:31:34.814321+00:00', '--job-id', '19', '--raw', '--subdir', 'DAGS_FOLDER/primeira_dag.py', '--cfg-path', '/tmp/tmp4vfwo8x8']
[2025-01-31T01:31:42.501+0000] {standard_task_runner.py:105} INFO - Job 19: Subtask tsk2
[2025-01-31T01:31:42.627+0000] {task_command.py:467} INFO - Running <TaskInstance: primeira_dag.tsk2 manual__2025-01-31T01:31:34.814321+00:00 [running]> on host 15928652fac1
[2025-01-31T01:31:42.765+0000] {taskinstance.py:3132} INFO - Exporting env vars: AIRFLOW_CTX_DAG_OWNER='***' AIRFLOW_CTX_DAG_ID='primeira_dag' AIRFLOW_CTX_TASK_ID='tsk2' AIRFLOW_CTX_EXECUTION_DATE='2025-01-31T01:31:34.814321+00:00' AIRFLOW_CTX_TRY_NUMBER='1' AIRFLOW_CTX_DAG_RUN_ID='manual__2025-01-31T01:31:34.814321+00:00'
[2025-01-31T01:31:42.768+0000] {taskinstance.py:731} INFO - ::endgroup::
[2025-01-31T01:31:42.795+0000] {subprocess.py:78} INFO - Tmp dir root location: /tmp
[2025-01-31T01:31:42.796+0000] {subprocess.py:88} INFO - Running command: ['/usr/bin/bash', '-c', "sleep 5; echo 'Hello World from Task 1"]
[2025-01-31T01:31:42.815+0000] {subprocess.py:99} INFO - Output:
[2025-01-31T01:31:42.817+0000] {subprocess.py:106} INFO - /usr/bin/bash: -c: line 1: unexpected EOF while looking for matching `''
[2025-01-31T01:31:42.818+0000] {subprocess.py:110} INFO - Command exited with return code 2
[2025-01-31T01:31:42.830+0000] {taskinstance.py:3311} ERROR - Task failed with exception
Traceback (most recent call last):
  File "/home/airflow/.local/lib/python3.12/site-packages/airflow/models/taskinstance.py", line 767, in _execute_task
    result = _execute_callable(context=context, **execute_callable_kwargs)
             ^^^^^^^^^^^^^^^^^^^^^^^^^^^^^^^^^^^^^^^^^^^^^^^^^^^^^^^^^^^^^
  File "/home/airflow/.local/lib/python3.12/site-packages/airflow/models/taskinstance.py", line 733, in _execute_callable
    return ExecutionCallableRunner(
           ^^^^^^^^^^^^^^^^^^^^^^^^
  File "/home/airflow/.local/lib/python3.12/site-packages/airflow/utils/operator_helpers.py", line 252, in run
    return self.func(*args, **kwargs)
           ^^^^^^^^^^^^^^^^^^^^^^^^^^
  File "/home/airflow/.local/lib/python3.12/site-packages/airflow/models/baseoperator.py", line 422, in wrapper
    return func(self, *args, **kwargs)
           ^^^^^^^^^^^^^^^^^^^^^^^^^^^
  File "/home/airflow/.local/lib/python3.12/site-packages/airflow/operators/bash.py", line 276, in execute
    raise AirflowException(
airflow.exceptions.AirflowException: Bash command failed. The command returned a non-zero exit code 2.
[2025-01-31T01:31:42.835+0000] {taskinstance.py:1225} INFO - Marking task as FAILED. dag_id=primeira_dag, task_id=tsk2, run_id=manual__2025-01-31T01:31:34.814321+00:00, execution_date=20250131T013134, start_date=20250131T013142, end_date=20250131T013142
[2025-01-31T01:31:42.845+0000] {taskinstance.py:340} INFO - ::group::Post task execution logs
[2025-01-31T01:31:42.845+0000] {standard_task_runner.py:124} ERROR - Failed to execute job 19 for task tsk2 (Bash command failed. The command returned a non-zero exit code 2.; 2978)
Traceback (most recent call last):
  File "/home/airflow/.local/lib/python3.12/site-packages/airflow/task/task_runner/standard_task_runner.py", line 117, in _start_by_fork
    ret = args.func(args, dag=self.dag)
          ^^^^^^^^^^^^^^^^^^^^^^^^^^^^^
  File "/home/airflow/.local/lib/python3.12/site-packages/airflow/cli/cli_config.py", line 49, in command
    return func(*args, **kwargs)
           ^^^^^^^^^^^^^^^^^^^^^
  File "/home/airflow/.local/lib/python3.12/site-packages/airflow/utils/cli.py", line 116, in wrapper
    return f(*args, **kwargs)
           ^^^^^^^^^^^^^^^^^^
  File "/home/airflow/.local/lib/python3.12/site-packages/airflow/cli/commands/task_command.py", line 483, in task_run
    task_return_code = _run_task_by_selected_method(args, _dag, ti)
                       ^^^^^^^^^^^^^^^^^^^^^^^^^^^^^^^^^^^^^^^^^^^^
  File "/home/airflow/.local/lib/python3.12/site-packages/airflow/cli/commands/task_command.py", line 256, in _run_task_by_selected_method
    return _run_raw_task(args, ti)
           ^^^^^^^^^^^^^^^^^^^^^^^
  File "/home/airflow/.local/lib/python3.12/site-packages/airflow/cli/commands/task_command.py", line 341, in _run_raw_task
    return ti._run_raw_task(
           ^^^^^^^^^^^^^^^^^
  File "/home/airflow/.local/lib/python3.12/site-packages/airflow/utils/session.py", line 97, in wrapper
    return func(*args, session=session, **kwargs)
           ^^^^^^^^^^^^^^^^^^^^^^^^^^^^^^^^^^^^^^
  File "/home/airflow/.local/lib/python3.12/site-packages/airflow/models/taskinstance.py", line 3005, in _run_raw_task
    return _run_raw_task(
           ^^^^^^^^^^^^^^
  File "/home/airflow/.local/lib/python3.12/site-packages/airflow/models/taskinstance.py", line 273, in _run_raw_task
    TaskInstance._execute_task_with_callbacks(
  File "/home/airflow/.local/lib/python3.12/site-packages/airflow/models/taskinstance.py", line 3159, in _execute_task_with_callbacks
    result = self._execute_task(context, task_orig)
             ^^^^^^^^^^^^^^^^^^^^^^^^^^^^^^^^^^^^^^
  File "/home/airflow/.local/lib/python3.12/site-packages/airflow/models/taskinstance.py", line 3183, in _execute_task
    return _execute_task(self, context, task_orig)
           ^^^^^^^^^^^^^^^^^^^^^^^^^^^^^^^^^^^^^^^
  File "/home/airflow/.local/lib/python3.12/site-packages/airflow/models/taskinstance.py", line 767, in _execute_task
    result = _execute_callable(context=context, **execute_callable_kwargs)
             ^^^^^^^^^^^^^^^^^^^^^^^^^^^^^^^^^^^^^^^^^^^^^^^^^^^^^^^^^^^^^
  File "/home/airflow/.local/lib/python3.12/site-packages/airflow/models/taskinstance.py", line 733, in _execute_callable
    return ExecutionCallableRunner(
           ^^^^^^^^^^^^^^^^^^^^^^^^
  File "/home/airflow/.local/lib/python3.12/site-packages/airflow/utils/operator_helpers.py", line 252, in run
    return self.func(*args, **kwargs)
           ^^^^^^^^^^^^^^^^^^^^^^^^^^
  File "/home/airflow/.local/lib/python3.12/site-packages/airflow/models/baseoperator.py", line 422, in wrapper
    return func(self, *args, **kwargs)
           ^^^^^^^^^^^^^^^^^^^^^^^^^^^
  File "/home/airflow/.local/lib/python3.12/site-packages/airflow/operators/bash.py", line 276, in execute
    raise AirflowException(
airflow.exceptions.AirflowException: Bash command failed. The command returned a non-zero exit code 2.
[2025-01-31T01:31:42.865+0000] {local_task_job_runner.py:266} INFO - Task exited with return code 1
[2025-01-31T01:31:42.900+0000] {taskinstance.py:3895} INFO - 0 downstream tasks scheduled from follow-on schedule check
[2025-01-31T01:31:42.903+0000] {local_task_job_runner.py:245} INFO - ::endgroup::
